Workbook

Sheet Hướng dẫn
A1: HƯỚNG DẪN SỬ DỤNG
A2: Tạo từ file SU.xlsx — dữ liệu 01/10 đến 05/10/2026.
A4: Sheet | B4: Dùng để
A5: Tổng hợp | B5: Xem nhanh: số dư quỹ, chi theo loại, nạp/đơn/rút theo nhân viên, thu chi theo từng ngày. Chỉ xem, không sửa.
A6: Thu Chi | B6: NHẬP mọi khoản tiền thu vào / chi ra. Ghi số dương vào cột Thu hoặc Chi. Cột Số dư tự tính.
A7: Giao dịch TK | B7: NHẬP nạp / đơn / rút của từng tài khoản khách, theo nhân viên. Rút ghi số dương.
A8: Theo TK | B8: Tổng hợp theo tên tài khoản. Thêm TK mới vào cuối cột A.
A9: Danh mục | B9: Danh sách nhân viên, loại thu chi, người chi/nhận (để chọn) và Số dư đầu kỳ (ô vàng).
A10: Đối chiếu file cũ | B10: So sánh các tổng gõ tay trong file cũ với số tính lại + danh sách điểm cần xác nhận.
A12: Quy ước màu
A13: Chữ xanh dương | B13: Ô nhập liệu — được sửa.
A14: Chữ đen | B14: Công thức — không sửa.
A15: Chữ xanh lá | B15: Lấy từ sheet khác.
A16: Nền vàng | B16: Ô cần điền (Số dư đầu kỳ).
A17: Nền cam | B17: Dòng có nghi vấn, cần kiểm tra lại.
A19: Ví dụ dòng Thu Chi | B19: 06/10/2026 | SU | Nguyên liệu | (Thu trống) | 1.500 | Mua sim | |
A20: Ví dụ dòng Giao dịch | B20: 06/10/2026 | WINDI | abc123 | 500 | | 200 |
A21: Lưu ý | B21: Mỗi sheet nhập liệu có sẵn 500 dòng có định dạng; các bảng tổng hợp đã tính sẵn cho đủ 500 dòng.

Sheet Tổng hợp
A1: TỔNG HỢP THU CHI THÁNG 10/2026
A2: Toàn bộ số trên sheet này là công thức — không cần sửa tay.
A4: 1. QUỸ | D4: Chi theo loại
A5: Số dư đầu kỳ | B5: ='Danh mục'!F5 -> 0 | D5: Loại | E5: Thu | F5: Chi | G5: % tổng chi
A6: Tổng thu | B6: =SUM('Thu Chi'!$D$5:$D$504) -> 349200 | D6: ='Danh mục'!B5 -> Nhận tiền | E6: =SUMIFS('Thu Chi'!$D$5:$D$504,'Thu Chi'!$C$5:$C$504,D6) -> 349200 | F6: =SUMIFS('Thu Chi'!$E$5:$E$504,'Thu Chi'!$C$5:$C$504,D6) -> 0 | G6: =IF($B$7=0,0,F6/$B$7) -> 0
A7: Tổng chi | B7: =SUM('Thu Chi'!$E$5:$E$504) -> 113194 | D7: ='Danh mục'!B6 -> Hoa hồng | E7: =SUMIFS('Thu Chi'!$D$5:$D$504,'Thu Chi'!$C$5:$C$504,D7) -> 0 | F7: =SUMIFS('Thu Chi'!$E$5:$E$504,'Thu Chi'!$C$5:$C$504,D7) -> 42572 | G7: =IF($B$7=0,0,F7/$B$7) -> 0.37609767
A8: Số dư cuối kỳ | B8: =B5+B6-B7 -> 236006 | D8: ='Danh mục'!B7 -> Nguyên liệu | E8: =SUMIFS('Thu Chi'!$D$5:$D$504,'Thu Chi'!$C$5:$C$504,D8) -> 0 | F8: =SUMIFS('Thu Chi'!$E$5:$E$504,'Thu Chi'!$C$5:$C$504,D8) -> 18250 | G8: =IF($B$7=0,0,F8/$B$7) -> 0.16122763
D9: ='Danh mục'!B8 -> Mua sắm | E9: =SUMIFS('Thu Chi'!$D$5:$D$504,'Thu Chi'!$C$5:$C$504,D9) -> 0 | F9: =SUMIFS('Thu Chi'!$E$5:$E$504,'Thu Chi'!$C$5:$C$504,D9) -> 25646 | G9: =IF($B$7=0,0,F9/$B$7) -> 0.22656678
D10: ='Danh mục'!B9 -> Trả nền tảng | E10: =SUMIFS('Thu Chi'!$D$5:$D$504,'Thu Chi'!$C$5:$C$504,D10) -> 0 | F10: =SUMIFS('Thu Chi'!$E$5:$E$504,'Thu Chi'!$C$5:$C$504,D10) -> 20000 | G10: =IF($B$7=0,0,F10/$B$7) -> 0.17668781
D11: ='Danh mục'!B10 -> Ứng | E11: =SUMIFS('Thu Chi'!$D$5:$D$504,'Thu Chi'!$C$5:$C$504,D11) -> 0 | F11: =SUMIFS('Thu Chi'!$E$5:$E$504,'Thu Chi'!$C$5:$C$504,D11) -> 0 | G11: =IF($B$7=0,0,F11/$B$7) -> 0
D12: ='Danh mục'!B11 -> Khác | E12: =SUMIFS('Thu Chi'!$D$5:$D$504,'Thu Chi'!$C$5:$C$504,D12) -> 0 | F12: =SUMIFS('Thu Chi'!$E$5:$E$504,'Thu Chi'!$C$5:$C$504,D12) -> 6726 | G12: =IF($B$7=0,0,F12/$B$7) -> 0.059420111
D13: Cộng | E13: =SUM(E6:E12) -> 349200 | F13: =SUM(F6:F12) -> 113194 | G13: =SUM(G6:G12) -> 1
D14: =IF(AND(E13=B6,F13=B7),"✓ Khớp tổng","⚠ Có dòng chưa chọn Loại") -> ✓ Khớp tổng
A16: 2. NẠP / ĐƠN / RÚT THEO NHÂN VIÊN
A17: Nhân viên / Đại lý | B17: Nạp | C17: Đơn | D17: Rút | E17: Nạp − Rút | F17: Nạp + Đơn | G17: Số dòng GD | H17: Hoa hồng đã chi
A18: ='Danh mục'!A5 -> WINDI | B18: =SUMIFS('Giao dịch TK'!$D$5:$D$504,'Giao dịch TK'!$B$5:$B$504,$A18) -> 21700 | C18: =SUMIFS('Giao dịch TK'!$E$5:$E$504,'Giao dịch TK'!$B$5:$B$504,$A18) -> 52000 | D18: =SUMIFS('Giao dịch TK'!$F$5:$F$504,'Giao dịch TK'!$B$5:$B$504,$A18) -> 2269 | E18: =B18-D18 -> 19431 | F18: =B18+C18 -> 73700 | G18: =COUNTIFS('Giao dịch TK'!$B$5:$B$504,$A18) -> 19 | H18: =SUMIFS('Thu Chi'!$E$5:$E$504,'Thu Chi'!$C$5:$C$504,"Hoa hồng",'Thu Chi'!$B$5:$B$504,"WINDY") -> 23772
A19: ='Danh mục'!A6 -> CAO TIẾN | B19: =SUMIFS('Giao dịch TK'!$D$5:$D$504,'Giao dịch TK'!$B$5:$B$504,$A19) -> 34230 | C19: =SUMIFS('Giao dịch TK'!$E$5:$E$504,'Giao dịch TK'!$B$5:$B$504,$A19) -> 23190 | D19: =SUMIFS('Giao dịch TK'!$F$5:$F$504,'Giao dịch TK'!$B$5:$B$504,$A19) -> 1320 | E19: =B19-D19 -> 32910 | F19: =B19+C19 -> 57420 | G19: =COUNTIFS('Giao dịch TK'!$B$5:$B$504,$A19) -> 26 | H19: 0
A20: ='Danh mục'!A7 -> SU | B20: =SUMIFS('Giao dịch TK'!$D$5:$D$504,'Giao dịch TK'!$B$5:$B$504,$A20) -> 8210 | C20: =SUMIFS('Giao dịch TK'!$E$5:$E$504,'Giao dịch TK'!$B$5:$B$504,$A20) -> 9200 | D20: =SUMIFS('Giao dịch TK'!$F$5:$F$504,'Giao dịch TK'!$B$5:$B$504,$A20) -> 751 | E20: =B20-D20 -> 7459 | F20: =B20+C20 -> 17410 | G20: =COUNTIFS('Giao dịch TK'!$B$5:$B$504,$A20) -> 6 | H20: 0
A21: ='Danh mục'!A8 -> CHƯA RÕ (bảng cột Y) | B21: =SUMIFS('Giao dịch TK'!$D$5:$D$504,'Giao dịch TK'!$B$5:$B$504,$A21) -> 750 | C21: =SUMIFS('Giao dịch TK'!$E$5:$E$504,'Giao dịch TK'!$B$5:$B$504,$A21) -> 0 | D21: =SUMIFS('Giao dịch TK'!$F$5:$F$504,'Giao dịch TK'!$B$5:$B$504,$A21) -> 500 | E21: =B21-D21 -> 250 | F21: =B21+C21 -> 750 | G21: =COUNTIFS('Giao dịch TK'!$B$5:$B$504,$A21) -> 3 | H21: 0
A22: ='Danh mục'!A9 -> ĐẠI LÝ NGỌC LINH 65 | B22: =SUMIFS('Giao dịch TK'!$D$5:$D$504,'Giao dịch TK'!$B$5:$B$504,$A22) -> 4000 | C22: =SUMIFS('Giao dịch TK'!$E$5:$E$504,'Giao dịch TK'!$B$5:$B$504,$A22) -> 0 | D22: =SUMIFS('Giao dịch TK'!$F$5:$F$504,'Giao dịch TK'!$B$5:$B$504,$A22) -> 0 | E22: =B22-D22 -> 4000 | F22: =B22+C22 -> 4000 | G22: =COUNTIFS('Giao dịch TK'!$B$5:$B$504,$A22) -> 2 | H22: =SUMIFS('Thu Chi'!$E$5:$E$504,'Thu Chi'!$C$5:$C$504,"Hoa hồng",'Thu Chi'!$B$5:$B$504,"ĐẠI LÝ NGỌC LINH") -> 5200
A23: ='Danh mục'!A10 -> RICON | B23: =SUMIFS('Giao dịch TK'!$D$5:$D$504,'Giao dịch TK'!$B$5:$B$504,$A23) -> 3500 | C23: =SUMIFS('Giao dịch TK'!$E$5:$E$504,'Giao dịch TK'!$B$5:$B$504,$A23) -> 0 | D23: =SUMIFS('Giao dịch TK'!$F$5:$F$504,'Giao dịch TK'!$B$5:$B$504,$A23) -> 0 | E23: =B23-D23 -> 3500 | F23: =B23+C23 -> 3500 | G23: =COUNTIFS('Giao dịch TK'!$B$5:$B$504,$A23) -> 2 | H23: 0
A24: Cộng | B24: =SUM(B18:B23) -> 72390 | C24: =SUM(C18:C23) -> 84390 | D24: =SUM(D18:D23) -> 4840 | E24: =SUM(E18:E23) -> 67550 | F24: =SUM(F18:F23) -> 156780 | G24: =SUM(G18:G23) -> 58 | H24: =SUM(H18:H23) -> 28972
A25: Cột 'Hoa hồng đã chi' lấy từ sheet Thu Chi (Loại = Hoa hồng, theo tên người nhận).
A27: 3. THEO NGÀY
A28: Ngày | B28: Thu | C28: Chi | D28: Thu − Chi | E28: Số dư cuối ngày | F28: Nạp (TK) | G28: Đơn (TK) | H28: Rút (TK)
A29: =DATE(2026,10,1) -> 46296 | B29: =SUMIFS('Thu Chi'!$D$5:$D$504,'Thu Chi'!$A$5:$A$504,$A29) -> 0 | C29: =SUMIFS('Thu Chi'!$E$5:$E$504,'Thu Chi'!$A$5:$A$504,$A29) -> 14950 | D29: =B29-C29 -> -14950 | E29: =$B$5+SUM($D$29:D29) -> -14950 | F29: =SUMIFS('Giao dịch TK'!$D$5:$D$504,'Giao dịch TK'!$A$5:$A$504,$A29) -> 23760 | G29: =SUMIFS('Giao dịch TK'!$E$5:$E$504,'Giao dịch TK'!$A$5:$A$504,$A29) -> 20000 | H29: =SUMIFS('Giao dịch TK'!$F$5:$F$504,'Giao dịch TK'!$A$5:$A$504,$A29) -> 1359
A30: =A29+1 -> 46297 | B30: =SUMIFS('Thu Chi'!$D$5:$D$504,'Thu Chi'!$A$5:$A$504,$A30) -> 9200 | C30: =SUMIFS('Thu Chi'!$E$5:$E$504,'Thu Chi'!$A$5:$A$504,$A30) -> 24917 | D30: =B30-C30 -> -15717 | E30: =$B$5+SUM($D$29:D30) -> -30667 | F30: =SUMIFS('Giao dịch TK'!$D$5:$D$504,'Giao dịch TK'!$A$5:$A$504,$A30) -> 4050 | G30: =SUMIFS('Giao dịch TK'!$E$5:$E$504,'Giao dịch TK'!$A$5:$A$504,$A30) -> 16000 | H30: =SUMIFS('Giao dịch TK'!$F$5:$F$504,'Giao dịch TK'!$A$5:$A$504,$A30) -> 1161
A31: =A30+1 -> 46298 | B31: =SUMIFS('Thu Chi'!$D$5:$D$504,'Thu Chi'!$A$5:$A$504,$A31) -> 40000 | C31: =SUMIFS('Thu Chi'!$E$5:$E$504,'Thu Chi'!$A$5:$A$504,$A31) -> 42001 | D31: =B31-C31 -> -2001 | E31: =$B$5+SUM($D$29:D31) -> -32668 | F31: =SUMIFS('Giao dịch TK'!$D$5:$D$504,'Giao dịch TK'!$A$5:$A$504,$A31) -> 28980 | G31: =SUMIFS('Giao dịch TK'!$E$5:$E$504,'Giao dịch TK'!$A$5:$A$504,$A31) -> 10600 | H31: =SUMIFS('Giao dịch TK'!$F$5:$F$504,'Giao dịch TK'!$A$5:$A$504,$A31) -> 1620
A32: =A31+1 -> 46299 | B32: =SUMIFS('Thu Chi'!$D$5:$D$504,'Thu Chi'!$A$5:$A$504,$A32) -> 300000 | C32: =SUMIFS('Thu Chi'!$E$5:$E$504,'Thu Chi'!$A$5:$A$504,$A32) -> 8826 | D32: =B32-C32 -> 291174 | E32: =$B$5+SUM($D$29:D32) -> 258506 | F32: =SUMIFS('Giao dịch TK'!$D$5:$D$504,'Giao dịch TK'!$A$5:$A$504,$A32) -> 7500 | G32: =SUMIFS('Giao dịch TK'!$E$5:$E$504,'Giao dịch TK'!$A$5:$A$504,$A32) -> 29190 | H32: =SUMIFS('Giao dịch TK'!$F$5:$F$504,'Giao dịch TK'!$A$5:$A$504,$A32) -> 0
A33: =A32+1 -> 46300 | B33: =SUMIFS('Thu Chi'!$D$5:$D$504,'Thu Chi'!$A$5:$A$504,$A33) -> 0 | C33: =SUMIFS('Thu Chi'!$E$5:$E$504,'Thu Chi'!$A$5:$A$504,$A33) -> 22500 | D33: =B33-C33 -> -22500 | E33: =$B$5+SUM($D$29:D33) -> 236006 | F33: =SUMIFS('Giao dịch TK'!$D$5:$D$504,'Giao dịch TK'!$A$5:$A$504,$A33) -> 4100 | G33: =SUMIFS('Giao dịch TK'!$E$5:$E$504,'Giao dịch TK'!$A$5:$A$504,$A33) -> 8600 | H33: =SUMIFS('Giao dịch TK'!$F$5:$F$504,'Giao dịch TK'!$A$5:$A$504,$A33) -> 700
A34: =A33+1 -> 46301 | B34: =SUMIFS('Thu Chi'!$D$5:$D$504,'Thu Chi'!$A$5:$A$504,$A34) -> 0 | C34: =SUMIFS('Thu Chi'!$E$5:$E$504,'Thu Chi'!$A$5:$A$504,$A34) -> 0 | D34: =B34-C34 -> 0 | E34: =$B$5+SUM($D$29:D34) -> 236006 | F34: =SUMIFS('Giao dịch TK'!$D$5:$D$504,'Giao dịch TK'!$A$5:$A$504,$A34) -> 0 | G34: =SUMIFS('Giao dịch TK'!$E$5:$E$504,'Giao dịch TK'!$A$5:$A$504,$A34) -> 0 | H34: =SUMIFS('Giao dịch TK'!$F$5:$F$504,'Giao dịch TK'!$A$5:$A$504,$A34) -> 0
A35: =A34+1 -> 46302 | B35: =SUMIFS('Thu Chi'!$D$5:$D$504,'Thu Chi'!$A$5:$A$504,$A35) -> 0 | C35: =SUMIFS('Thu Chi'!$E$5:$E$504,'Thu Chi'!$A$5:$A$504,$A35) -> 0 | D35: =B35-C35 -> 0 | E35: =$B$5+SUM($D$29:D35) -> 236006 | F35: =SUMIFS('Giao dịch TK'!$D$5:$D$504,'Giao dịch TK'!$A$5:$A$504,$A35) -> 0 | G35: =SUMIFS('Giao dịch TK'!$E$5:$E$504,'Giao dịch TK'!$A$5:$A$504,$A35) -> 0 | H35: =SUMIFS('Giao dịch TK'!$F$5:$F$504,'Giao dịch TK'!$A$5:$A$504,$A35) -> 0
A36: =A35+1 -> 46303 | B36: =SUMIFS('Thu Chi'!$D$5:$D$504,'Thu Chi'!$A$5:$A$504,$A36) -> 0 | C36: =SUMIFS('Thu Chi'!$E$5:$E$504,'Thu Chi'!$A$5:$A$504,$A36) -> 0 | D36: =B36-C36 -> 0 | E36: =$B$5+SUM($D$29:D36) -> 236006 | F36: =SUMIFS('Giao dịch TK'!$D$5:$D$504,'Giao dịch TK'!$A$5:$A$504,$A36) -> 0 | G36: =SUMIFS('Giao dịch TK'!$E$5:$E$504,'Giao dịch TK'!$A$5:$A$504,$A36) -> 0 | H36: =SUMIFS('Giao dịch TK'!$F$5:$F$504,'Giao dịch TK'!$A$5:$A$504,$A36) -> 0
A37: =A36+1 -> 46304 | B37: =SUMIFS('Thu Chi'!$D$5:$D$504,'Thu Chi'!$A$5:$A$504,$A37) -> 0 | C37: =SUMIFS('Thu Chi'!$E$5:$E$504,'Thu Chi'!$A$5:$A$504,$A37) -> 0 | D37: =B37-C37 -> 0 | E37: =$B$5+SUM($D$29:D37) -> 236006 | F37: =SUMIFS('Giao dịch TK'!$D$5:$D$504,'Giao dịch TK'!$A$5:$A$504,$A37) -> 0 | G37: =SUMIFS('Giao dịch TK'!$E$5:$E$504,'Giao dịch TK'!$A$5:$A$504,$A37) -> 0 | H37: =SUMIFS('Giao dịch TK'!$F$5:$F$504,'Giao dịch TK'!$A$5:$A$504,$A37) -> 0
A38: =A37+1 -> 46305 | B38: =SUMIFS('Thu Chi'!$D$5:$D$504,'Thu Chi'!$A$5:$A$504,$A38) -> 0 | C38: =SUMIFS('Thu Chi'!$E$5:$E$504,'Thu Chi'!$A$5:$A$504,$A38) -> 0 | D38: =B38-C38 -> 0 | E38: =$B$5+SUM($D$29:D38) -> 236006 | F38: =SUMIFS('Giao dịch TK'!$D$5:$D$504,'Giao dịch TK'!$A$5:$A$504,$A38) -> 0 | G38: =SUMIFS('Giao dịch TK'!$E$5:$E$504,'Giao dịch TK'!$A$5:$A$504,$A38) -> 0 | H38: =SUMIFS('Giao dịch TK'!$F$5:$F$504,'Giao dịch TK'!$A$5:$A$504,$A38) -> 0
A39: =A38+1 -> 46306 | B39: =SUMIFS('Thu Chi'!$D$5:$D$504,'Thu Chi'!$A$5:$A$504,$A39) -> 0 | C39: =SUMIFS('Thu Chi'!$E$5:$E$504,'Thu Chi'!$A$5:$A$504,$A39) -> 0 | D39: =B39-C39 -> 0 | E39: =$B$5+SUM($D$29:D39) -> 236006 | F39: =SUMIFS('Giao dịch TK'!$D$5:$D$504,'Giao dịch TK'!$A$5:$A$504,$A39) -> 0 | G39: =SUMIFS('Giao dịch TK'!$E$5:$E$504,'Giao dịch TK'!$A$5:$A$504,$A39) -> 0 | H39: =SUMIFS('Giao dịch TK'!$F$5:$F$504,'Giao dịch TK'!$A$5:$A$504,$A39) -> 0
A40: =A39+1 -> 46307 | B40: =SUMIFS('Thu Chi'!$D$5:$D$504,'Thu Chi'!$A$5:$A$504,$A40) -> 0 | C40: =SUMIFS('Thu Chi'!$E$5:$E$504,'Thu Chi'!$A$5:$A$504,$A40) -> 0 | D40: =B40-C40 -> 0 | E40: =$B$5+SUM($D$29:D40) -> 236006 | F40: =SUMIFS('Giao dịch TK'!$D$5:$D$504,'Giao dịch TK'!$A$5:$A$504,$A40) -> 0 | G40: =SUMIFS('Giao dịch TK'!$E$5:$E$504,'Giao dịch TK'!$A$5:$A$504,$A40) -> 0 | H40: =SUMIFS('Giao dịch TK'!$F$5:$F$504,'Giao dịch TK'!$A$5:$A$504,$A40) -> 0
A41: =A40+1 -> 46308 | B41: =SUMIFS('Thu Chi'!$D$5:$D$504,'Thu Chi'!$A$5:$A$504,$A41) -> 0 | C41: =SUMIFS('Thu Chi'!$E$5:$E$504,'Thu Chi'!$A$5:$A$504,$A41) -> 0 | D41: =B41-C41 -> 0 | E41: =$B$5+SUM($D$29:D41) -> 236006 | F41: =SUMIFS('Giao dịch TK'!$D$5:$D$504,'Giao dịch TK'!$A$5:$A$504,$A41) -> 0 | G41: =SUMIFS('Giao dịch TK'!$E$5:$E$504,'Giao dịch TK'!$A$5:$A$504,$A41) -> 0 | H41: =SUMIFS('Giao dịch TK'!$F$5:$F$504,'Giao dịch TK'!$A$5:$A$504,$A41) -> 0
... A59: =A58+1 -> 46326 | B59: =SUMIFS('Thu Chi'!$D$5:$D$504,'Thu Chi'!$A$5:$A$504,$A59) -> 0 | C59: =SUMIFS('Thu Chi'!$E$5:$E$504,'Thu Chi'!$A$5:$A$504,$A59) -> 0 | D59: =B59-C59 -> 0 | E59: =$B$5+SUM($D$29:D59) -> 236006 | F59: =SUMIFS('Giao dịch TK'!$D$5:$D$504,'Giao dịch TK'!$A$5:$A$504,$A59) -> 0 | G59: =SUMIFS('Giao dịch TK'!$E$5:$E$504,'Giao dịch TK'!$A$5:$A$504,$A59) -> 0 | H59: =SUMIFS('Giao dịch TK'!$F$5:$F$504,'Giao dịch TK'!$A$5:$A$504,$A59) -> 0
A60: Không rõ ngày | B60: =SUMIFS('Thu Chi'!$D$5:$D$504,'Thu Chi'!$A$5:$A$504,"",'Thu Chi'!$D$5:$D$504,"<>") -> 0 | C60: =SUMIFS('Thu Chi'!$E$5:$E$504,'Thu Chi'!$A$5:$A$504,"",'Thu Chi'!$E$5:$E$504,"<>") -> 0 | D60: =B60-C60 -> 0 | F60: =SUMIFS('Giao dịch TK'!$D$5:$D$504,'Giao dịch TK'!$A$5:$A$504,"",'Giao dịch TK'!$B$5:$B$504,"<>") -> 4000 | G60: =SUMIFS('Giao dịch TK'!$E$5:$E$504,'Giao dịch TK'!$A$5:$A$504,"",'Giao dịch TK'!$B$5:$B$504,"<>") -> 0 | H60: =SUMIFS('Giao dịch TK'!$F$5:$F$504,'Giao dịch TK'!$A$5:$A$504,"",'Giao dịch TK'!$B$5:$B$504,"<>") -> 0
...

Sheet Danh mục
A1: DANH MỤC
A2: Thêm tên mới vào cuối mỗi cột — danh sách chọn ở các sheet khác sẽ tự cập nhật.
A4: Nhân viên / Đại lý | B4: Loại thu chi | C4: Người chi / nhận
A5: WINDI | B5: Nhận tiền | C5: SU | E5: Số dư đầu kỳ (quỹ): | F5: 0
A6: CAO TIẾN | B6: Hoa hồng | C6: GIA
A7: SU | B7: Nguyên liệu | C7: CAO TIẾN
A8: CHƯA RÕ (bảng cột Y) | B8: Mua sắm | C8: LOUIS
A9: ĐẠI LÝ NGỌC LINH 65 | B9: Trả nền tảng | C9: A CHÁN
A10: RICON | B10: Ứng | C10: WINDY
B11: Khác | C11: ĐẠI LÝ NGỌC LINH
C12: MÙ TẠT

Sheet Thu Chi
A1: SỔ THU CHI THÁNG 10/2026
A2: Mỗi dòng = 1 khoản. Ghi số tiền vào cột THU hoặc CHI (số dương). Cột Số dư tự tính.
A4: Ngày | B4: Người chi / nhận | C4: Loại | D4: Thu | E4: Chi | F4: Số dư | G4: Nội dung | H4: Nguồn (file cũ) | I4: Ghi chú
A5: 46296 | B5: CAO TIẾN | C5: Nguyên liệu | E5: 4600 | F5: =IF(AND(D5="",E5=""),"",'Danh mục'!$F$5+SUM($D$5:D5)-SUM($E$5:E5)) -> -4600 | G5: Duy Mạnh | H5: THU CHI!E3
A6: 46296 | B6: CAO TIẾN | C6: Nguyên liệu | E6: 2100 | F6: =IF(AND(D6="",E6=""),"",'Danh mục'!$F$5+SUM($D$5:D6)-SUM($E$5:E6)) -> -6700 | G6: Tele nhóm | H6: THU CHI!E4
A7: 46296 | B7: CAO TIẾN | C7: Nguyên liệu | E7: 5400 | F7: =IF(AND(D7="",E7=""),"",'Danh mục'!$F$5+SUM($D$5:D7)-SUM($E$5:E7)) -> -12100 | G7: Rin | H7: THU CHI!E5
A8: 46296 | B8: CAO TIẾN | C8: Nguyên liệu | E8: 400 | F8: =IF(AND(D8="",E8=""),"",'Danh mục'!$F$5+SUM($D$5:D8)-SUM($E$5:E8)) -> -12500 | G8: Tele nhóm | H8: THU CHI!E6
A9: 46296 | B9: LOUIS | C9: Nguyên liệu | E9: 350 | F9: =IF(AND(D9="",E9=""),"",'Danh mục'!$F$5+SUM($D$5:D9)-SUM($E$5:E9)) -> -12850 | G9: Nâng sao tele | H9: THU CHI!E9
A10: 46296 | B10: A CHÁN | C10: Nguyên liệu | E10: 2100 | F10: =IF(AND(D10="",E10=""),"",'Danh mục'!$F$5+SUM($D$5:D10)-SUM($E$5:E10)) -> -14950 | H10: THU CHI!E12 | I10: File gốc không ghi nội dung
A11: 46297 | B11: SU | C11: Nhận tiền | D11: 9200 | F11: =IF(AND(D11="",E11=""),"",'Danh mục'!$F$5+SUM($D$5:D11)-SUM($E$5:E11)) -> -5750 | H11: su!C2
A12: 46297 | B12: SU | C12: Mua sắm | E12: 6417 | F12: =IF(AND(D12="",E12=""),"",'Danh mục'!$F$5+SUM($D$5:D12)-SUM($E$5:E12)) -> -12167 | G12: Mua tủ lạnh | H12: su!D2
A13: 46297 | B13: SU | C13: Nguyên liệu | E13: 2300 | F13: =IF(AND(D13="",E13=""),"",'Danh mục'!$F$5+SUM($D$5:D13)-SUM($E$5:E13)) -> -14467 | G13: Nguyên liệu nhóm | H13: su!D3 = THU CHI!E18 | I13: Có ở cả 2 sheet cũ — chỉ ghi 1 lần
A14: 46297 | B14: LOUIS | C14: Nguyên liệu | E14: 1000 | F14: =IF(AND(D14="",E14=""),"",'Danh mục'!$F$5+SUM($D$5:D14)-SUM($E$5:E14)) -> -15467 | G14: Mua bank | H14: THU CHI!E15
A15: 46297 | B15: ĐẠI LÝ NGỌC LINH | C15: Hoa hồng | E15: 5200 | F15: =IF(AND(D15="",E15=""),"",'Danh mục'!$F$5+SUM($D$5:D15)-SUM($E$5:E15)) -> -20667 | G15: Hoa hồng | H15: HH THANG 10!D2
A16: 46297 | B16: LOUIS | C16: Hoa hồng | E16: 10000 | F16: =IF(AND(D16="",E16=""),"",'Danh mục'!$F$5+SUM($D$5:D16)-SUM($E$5:E16)) -> -30667 | G16: Hoa hồng | H16: HH THANG 10!D3
A17: 46298 | B17: SU | C17: Nhận tiền | D17: 25000 | F17: =IF(AND(D17="",E17=""),"",'Danh mục'!$F$5+SUM($D$5:D17)-SUM($E$5:E17)) -> -5667 | H17: su!C4
A18: 46298 | B18: SU | C18: Nhận tiền | D18: 15000 | F18: =IF(AND(D18="",E18=""),"",'Danh mục'!$F$5+SUM($D$5:D18)-SUM($E$5:E18)) -> 9333 | H18: su!C5
A19: 46298 | B19: GIA | C19: Mua sắm | E19: 11400 | F19: =IF(AND(D19="",E19=""),"",'Danh mục'!$F$5+SUM($D$5:D19)-SUM($E$5:E19)) -> -2067 | G19: Mua máy tính | H19: su!D4
A20: 46298 | B20: GIA | C20: Mua sắm | E20: 529 | F20: =IF(AND(D20="",E20=""),"",'Danh mục'!$F$5+SUM($D$5:D20)-SUM($E$5:E20)) -> -2596 | G20: Mua quạt nhân viên | H20: su!D5
A21: 46298 | B21: GIA | C21: Mua sắm | E21: 2700 | F21: =IF(AND(D21="",E21=""),"",'Danh mục'!$F$5+SUM($D$5:D21)-SUM($E$5:E21)) -> -5296 | G21: Mua bồn cầu | H21: su!D6
A22: 46298 | B22: MÙ TẠT | C22: Hoa hồng | E22: 3600 | F22: =IF(AND(D22="",E22=""),"",'Danh mục'!$F$5+SUM($D$5:D22)-SUM($E$5:E22)) -> -8896 | G22: Hoa hồng | H22: HH THANG 10!D4
A23: 46298 | B23: WINDY | C23: Hoa hồng | E23: 23772 | F23: =IF(AND(D23="",E23=""),"",'Danh mục'!$F$5+SUM($D$5:D23)-SUM($E$5:E23)) -> -32668 | G23: Hoa hồng Windy | H23: su!D7 = HH THANG 10!D5 | I23: Có ở cả 2 sheet cũ — chỉ ghi 1 lần
A24: 46299 | B24: SU | C24: Nhận tiền | D24: 300000 | F24: =IF(AND(D24="",E24=""),"",'Danh mục'!$F$5+SUM($D$5:D24)-SUM($E$5:E24)) -> 267332 | H24: su!C8 | I24: KIỂM TRA: lớn gấp ~10 lần ngày khác, có thể gõ thừa số 0
A25: 46299 | B25: GIA | C25: Khác | E25: 2226 | F25: =IF(AND(D25="",E25=""),"",'Danh mục'!$F$5+SUM($D$5:D25)-SUM($E$5:E25)) -> 265106 | H25: su!D8 | I25: File gốc chỉ ghi 'GIA'
A26: 46299 | B26: GIA | C26: Khác | E26: 2000 | F26: =IF(AND(D26="",E26=""),"",'Danh mục'!$F$5+SUM($D$5:D26)-SUM($E$5:E26)) -> 263106 | H26: su!D9 | I26: File gốc chỉ ghi 'GIA'
A27: 46299 | B27: SU | C27: Mua sắm | E27: 4600 | F27: =IF(AND(D27="",E27=""),"",'Danh mục'!$F$5+SUM($D$5:D27)-SUM($E$5:E27)) -> 258506 | G27: Mua ss | H27: THU CHI!E19 | I27: Không có trong sheet 'su' cũ — cần xác nhận
A28: 46300 | B28: SU | C28: Trả nền tảng | E28: 20000 | F28: =IF(AND(D28="",E28=""),"",'Danh mục'!$F$5+SUM($D$5:D28)-SUM($E$5:E28)) -> 238506 | G28: Nền tảng | H28: su!D10
A29: 46300 | B29: GIA | C29: Khác | E29: 1500 | F29: =IF(AND(D29="",E29=""),"",'Danh mục'!$F$5+SUM($D$5:D29)-SUM($E$5:E29)) -> 237006 | H29: su!D11 | I29: File gốc chỉ ghi 'gia'
A30: 46300 | B30: GIA | C30: Khác | E30: 1000 | F30: =IF(AND(D30="",E30=""),"",'Danh mục'!$F$5+SUM($D$5:D30)-SUM($E$5:E30)) -> 236006 | H30: su!D12 | I30: File gốc chỉ ghi 'gia'
F31: =IF(AND(D31="",E31=""),"",'Danh mục'!$F$5+SUM($D$5:D31)-SUM($E$5:E31))
F32: =IF(AND(D32="",E32=""),"",'Danh mục'!$F$5+SUM($D$5:D32)-SUM($E$5:E32))
F33: =IF(AND(D33="",E33=""),"",'Danh mục'!$F$5+SUM($D$5:D33)-SUM($E$5:E33))
F34: =IF(AND(D34="",E34=""),"",'Danh mục'!$F$5+SUM($D$5:D34)-SUM($E$5:E34))
F35: =IF(AND(D35="",E35=""),"",'Danh mục'!$F$5+SUM($D$5:D35)-SUM($E$5:E35))
F36: =IF(AND(D36="",E36=""),"",'Danh mục'!$F$5+SUM($D$5:D36)-SUM($E$5:E36))
F37: =IF(AND(D37="",E37=""),"",'Danh mục'!$F$5+SUM($D$5:D37)-SUM($E$5:E37))
F38: =IF(AND(D38="",E38=""),"",'Danh mục'!$F$5+SUM($D$5:D38)-SUM($E$5:E38))
F39: =IF(AND(D39="",E39=""),"",'Danh mục'!$F$5+SUM($D$5:D39)-SUM($E$5:E39))
F40: =IF(AND(D40="",E40=""),"",'Danh mục'!$F$5+SUM($D$5:D40)-SUM($E$5:E40))
F41: =IF(AND(D41="",E41=""),"",'Danh mục'!$F$5+SUM($D$5:D41)-SUM($E$5:E41))
...

Sheet Giao dịch TK
A1: GIAO DỊCH NẠP / ĐƠN / RÚT THEO TÀI KHOẢN
A2: Rút ghi SỐ DƯƠNG. Mỗi dòng = 1 tài khoản trong 1 ngày.
A4: Ngày | B4: Nhân viên / Đại lý | C4: Tên TK | D4: Nạp | E4: Đơn | F4: Rút | G4: Nạp − Rút | H4: Nguồn (file cũ) | I4: Ghi chú
A5: 46296 | B5: WINDI | C5: khiem99z | D5: 50 | G5: =IF(AND(D5="",F5=""),"",N(D5)-N(F5)) -> 50 | H5: tháng 10!C5
A6: 46296 | B6: WINDI | C6: zinssha | D6: 5000 | E6: 15000 | G6: =IF(AND(D6="",F6=""),"",N(D6)-N(F6)) -> 5000 | H6: tháng 10!C6
A7: 46296 | B7: WINDI | C7: linhnhi6868 | D7: 3000 | G7: =IF(AND(D7="",F7=""),"",N(D7)-N(F7)) -> 3000 | H7: tháng 10!C7
A8: 46296 | B8: WINDI | C8: junjin91 | D8: 50 | F8: 307 | G8: =IF(AND(D8="",F8=""),"",N(D8)-N(F8)) -> -257 | H8: tháng 10!C8
A9: 46296 | B9: WINDI | C9: congacon | D9: 5000 | E9: 5000 | G9: =IF(AND(D9="",F9=""),"",N(D9)-N(F9)) -> 5000 | H9: tháng 10!C9
A10: 46296 | B10: WINDI | C10: andanh8386 | D10: 100 | F10: 101 | G10: =IF(AND(D10="",F10=""),"",N(D10)-N(F10)) -> -1 | H10: tháng 10!C10
A11: 46296 | B11: WINDI | C11: linh6868 | D11: 1000 | G11: =IF(AND(D11="",F11=""),"",N(D11)-N(F11)) -> 1000 | H11: tháng 10!C11
A12: 46296 | B12: WINDI | C12: beannie | D12: 150 | G12: =IF(AND(D12="",F12=""),"",N(D12)-N(F12)) -> 150 | H12: tháng 10!C12
A13: 46296 | B13: WINDI | C13: buingoc66 | D13: 200 | G13: =IF(AND(D13="",F13=""),"",N(D13)-N(F13)) -> 200 | H13: tháng 10!C13
A14: 46297 | B14: WINDI | C14: beannie | D14: 100 | F14: 206 | G14: =IF(AND(D14="",F14=""),"",N(D14)-N(F14)) -> -106 | H14: tháng 10!C17
A15: 46297 | B15: WINDI | C15: andanh8386 | D15: 200 | G15: =IF(AND(D15="",F15=""),"",N(D15)-N(F15)) -> 200 | H15: tháng 10!C18
A16: 46297 | B16: WINDI | C16: beannie | D16: 100 | G16: =IF(AND(D16="",F16=""),"",N(D16)-N(F16)) -> 100 | H16: tháng 10!C19
A17: 46297 | B17: WINDI | C17: buingoc66 | D17: 150 | F17: 955 | G17: =IF(AND(D17="",F17=""),"",N(D17)-N(F17)) -> -805 | H17: tháng 10!C20
A18: 46297 | B18: WINDI | C18: haithanh89 | D18: 3000 | E18: 6000 | G18: =IF(AND(D18="",F18=""),"",N(D18)-N(F18)) -> 3000 | H18: tháng 10!C21
A19: 46297 | B19: WINDI | C19: cao774 | D19: 300 | E19: 10000 | G19: =IF(AND(D19="",F19=""),"",N(D19)-N(F19)) -> 300 | H19: tháng 10!C22
A20: 46298 | B20: WINDI | C20: traidep2236 | D20: 3000 | E20: 6000 | G20: =IF(AND(D20="",F20=""),"",N(D20)-N(F20)) -> 3000 | H20: tháng 10!C26
A21: 46298 | B21: WINDI | C21: buingoc66 | D21: 250 | G21: =IF(AND(D21="",F21=""),"",N(D21)-N(F21)) -> 250 | H21: tháng 10!C27
A22: 46299 | B22: WINDI | C22: cao774 | E22: 10000 | G22: =IF(AND(D22="",F22=""),"",N(D22)-N(F22)) | H22: tháng 10!C28
A23: 46300 | B23: WINDI | C23: khiem99z | D23: 50 | F23: 700 | G23: =IF(AND(D23="",F23=""),"",N(D23)-N(F23)) -> -650 | H23: tháng 10!C29 | I23: File gốc ghi rút +700 (các dòng khác ghi số âm)
A24: 46296 | B24: CAO TIẾN | C24: vansuol123 | D24: 200 | F24: 100 | G24: =IF(AND(D24="",F24=""),"",N(D24)-N(F24)) -> 100 | H24: tháng 10!K4 | I24: Có thể là 'vansuong123' (gõ nhầm?)
A25: 46296 | B25: CAO TIẾN | C25: phanvandieu | D25: 3000 | G25: =IF(AND(D25="",F25=""),"",N(D25)-N(F25)) -> 3000 | H25: tháng 10!K5
A26: 46296 | B26: CAO TIẾN | C26: phandz9999 | D26: 1000 | G26: =IF(AND(D26="",F26=""),"",N(D26)-N(F26)) -> 1000 | H26: tháng 10!K6
A27: 46296 | B27: CAO TIẾN | C27: camon28 | D27: 4000 | G27: =IF(AND(D27="",F27=""),"",N(D27)-N(F27)) -> 4000 | H27: tháng 10!K7
A28: 46296 | B28: CAO TIẾN | C28: (không ghi tên) | F28: 100 | G28: =IF(AND(D28="",F28=""),"",N(D28)-N(F28)) -> -100 | H28: tháng 10!N8 | I28: File gốc thiếu tên TK
A29: 46297 | B29: CAO TIẾN | C29: havantung | D29: 50 | G29: =IF(AND(D29="",F29=""),"",N(D29)-N(F29)) -> 50 | H29: tháng 10!K11
A30: 46297 | B30: CAO TIẾN | C30: vansuong123 | D30: 100 | G30: =IF(AND(D30="",F30=""),"",N(D30)-N(F30)) -> 100 | H30: tháng 10!K12
A31: 46298 | B31: CAO TIẾN | C31: vansuong123 | D31: 100 | G31: =IF(AND(D31="",F31=""),"",N(D31)-N(F31)) -> 100 | H31: tháng 10!K15
A32: 46298 | B32: CAO TIẾN | C32: rang188 | D32: 2580 | G32: =IF(AND(D32="",F32=""),"",N(D32)-N(F32)) -> 2580 | H32: tháng 10!K16
A33: 46298 | B33: CAO TIẾN | C33: subhdantribcr2026 | D33: 4100 | F33: 1120 | G33: =IF(AND(D33="",F33=""),"",N(D33)-N(F33)) -> 2980 | H33: tháng 10!K17
A34: 46298 | B34: CAO TIẾN | C34: hieu1996 | D34: 1000 | G34: =IF(AND(D34="",F34=""),"",N(D34)-N(F34)) -> 1000 | H34: tháng 10!K18
A35: 46298 | B35: CAO TIẾN | C35: baomini8386 | D35: 50 | G35: =IF(AND(D35="",F35=""),"",N(D35)-N(F35)) -> 50 | H35: tháng 10!K19
A36: 46298 | B36: CAO TIẾN | C36: thuthuy07007 | D36: 10000 | G36: =IF(AND(D36="",F36=""),"",N(D36)-N(F36)) -> 10000 | H36: tháng 10!K20
A37: 46298 | B37: CAO TIẾN | C37: cuong1992 | D37: 100 | G37: =IF(AND(D37="",F37=""),"",N(D37)-N(F37)) -> 100 | H37: tháng 10!K21
A38: 46299 | B38: CAO TIẾN | C38: cuong1992 | D38: 2000 | G38: =IF(AND(D38="",F38=""),"",N(D38)-N(F38)) -> 2000 | H38: tháng 10!K22
A39: 46299 | B39: CAO TIẾN | C39: haidang186 | D39: 150 | G39: =IF(AND(D39="",F39=""),"",N(D39)-N(F39)) -> 150 | H39: tháng 10!K23
A40: 46299 | B40: CAO TIẾN | C40: nguoila12c | D40: 1000 | G40: =IF(AND(D40="",F40=""),"",N(D40)-N(F40)) -> 1000 | H40: tháng 10!K24
A41: 46299 | B41: CAO TIẾN | C41: nhatbcr678 | D41: 1200 | G41: =IF(AND(D41="",F41=""),"",N(D41)-N(F41)) -> 1200 | H41: tháng 10!K25
...

Sheet Theo TK
A1: TỔNG HỢP THEO TÀI KHOẢN
A2: Danh sách TK lấy từ dữ liệu hiện có. Thêm TK mới vào cuối cột A để theo dõi.
A4: Tên TK | B4: Nạp | C4: Đơn | D4: Rút | E4: Nạp − Rút | F4: Số lần GD
A5: (không ghi tên) | B5: =SUMIFS('Giao dịch TK'!$D$5:$D$504,'Giao dịch TK'!$C$5:$C$504,$A5) -> 500 | C5: =SUMIFS('Giao dịch TK'!$E$5:$E$504,'Giao dịch TK'!$C$5:$C$504,$A5) -> 0 | D5: =SUMIFS('Giao dịch TK'!$F$5:$F$504,'Giao dịch TK'!$C$5:$C$504,$A5) -> 600 | E5: =B5-D5 -> -100 | F5: =COUNTIFS('Giao dịch TK'!$C$5:$C$504,$A5) -> 2
A6: ah1234567 | B6: =SUMIFS('Giao dịch TK'!$D$5:$D$504,'Giao dịch TK'!$C$5:$C$504,$A6) -> 2500 | C6: =SUMIFS('Giao dịch TK'!$E$5:$E$504,'Giao dịch TK'!$C$5:$C$504,$A6) -> 0 | D6: =SUMIFS('Giao dịch TK'!$F$5:$F$504,'Giao dịch TK'!$C$5:$C$504,$A6) -> 0 | E6: =B6-D6 -> 2500 | F6: =COUNTIFS('Giao dịch TK'!$C$5:$C$504,$A6) -> 1
A7: andanh8386 | B7: =SUMIFS('Giao dịch TK'!$D$5:$D$504,'Giao dịch TK'!$C$5:$C$504,$A7) -> 300 | C7: =SUMIFS('Giao dịch TK'!$E$5:$E$504,'Giao dịch TK'!$C$5:$C$504,$A7) -> 0 | D7: =SUMIFS('Giao dịch TK'!$F$5:$F$504,'Giao dịch TK'!$C$5:$C$504,$A7) -> 101 | E7: =B7-D7 -> 199 | F7: =COUNTIFS('Giao dịch TK'!$C$5:$C$504,$A7) -> 2
A8: baomini8386 | B8: =SUMIFS('Giao dịch TK'!$D$5:$D$504,'Giao dịch TK'!$C$5:$C$504,$A8) -> 50 | C8: =SUMIFS('Giao dịch TK'!$E$5:$E$504,'Giao dịch TK'!$C$5:$C$504,$A8) -> 0 | D8: =SUMIFS('Giao dịch TK'!$F$5:$F$504,'Giao dịch TK'!$C$5:$C$504,$A8) -> 0 | E8: =B8-D8 -> 50 | F8: =COUNTIFS('Giao dịch TK'!$C$5:$C$504,$A8) -> 1
A9: beannie | B9: =SUMIFS('Giao dịch TK'!$D$5:$D$504,'Giao dịch TK'!$C$5:$C$504,$A9) -> 350 | C9: =SUMIFS('Giao dịch TK'!$E$5:$E$504,'Giao dịch TK'!$C$5:$C$504,$A9) -> 0 | D9: =SUMIFS('Giao dịch TK'!$F$5:$F$504,'Giao dịch TK'!$C$5:$C$504,$A9) -> 206 | E9: =B9-D9 -> 144 | F9: =COUNTIFS('Giao dịch TK'!$C$5:$C$504,$A9) -> 3
A10: buingoc66 | B10: =SUMIFS('Giao dịch TK'!$D$5:$D$504,'Giao dịch TK'!$C$5:$C$504,$A10) -> 600 | C10: =SUMIFS('Giao dịch TK'!$E$5:$E$504,'Giao dịch TK'!$C$5:$C$504,$A10) -> 0 | D10: =SUMIFS('Giao dịch TK'!$F$5:$F$504,'Giao dịch TK'!$C$5:$C$504,$A10) -> 955 | E10: =B10-D10 -> -355 | F10: =COUNTIFS('Giao dịch TK'!$C$5:$C$504,$A10) -> 3
A11: camon28 | B11: =SUMIFS('Giao dịch TK'!$D$5:$D$504,'Giao dịch TK'!$C$5:$C$504,$A11) -> 4000 | C11: =SUMIFS('Giao dịch TK'!$E$5:$E$504,'Giao dịch TK'!$C$5:$C$504,$A11) -> 0 | D11: =SUMIFS('Giao dịch TK'!$F$5:$F$504,'Giao dịch TK'!$C$5:$C$504,$A11) -> 0 | E11: =B11-D11 -> 4000 | F11: =COUNTIFS('Giao dịch TK'!$C$5:$C$504,$A11) -> 1
A12: cao774 | B12: =SUMIFS('Giao dịch TK'!$D$5:$D$504,'Giao dịch TK'!$C$5:$C$504,$A12) -> 300 | C12: =SUMIFS('Giao dịch TK'!$E$5:$E$504,'Giao dịch TK'!$C$5:$C$504,$A12) -> 20000 | D12: =SUMIFS('Giao dịch TK'!$F$5:$F$504,'Giao dịch TK'!$C$5:$C$504,$A12) -> 0 | E12: =B12-D12 -> 300 | F12: =COUNTIFS('Giao dịch TK'!$C$5:$C$504,$A12) -> 2
A13: congacon | B13: =SUMIFS('Giao dịch TK'!$D$5:$D$504,'Giao dịch TK'!$C$5:$C$504,$A13) -> 5000 | C13: =SUMIFS('Giao dịch TK'!$E$5:$E$504,'Giao dịch TK'!$C$5:$C$504,$A13) -> 5000 | D13: =SUMIFS('Giao dịch TK'!$F$5:$F$504,'Giao dịch TK'!$C$5:$C$504,$A13) -> 0 | E13: =B13-D13 -> 5000 | F13: =COUNTIFS('Giao dịch TK'!$C$5:$C$504,$A13) -> 1
A14: cuong1992 | B14: =SUMIFS('Giao dịch TK'!$D$5:$D$504,'Giao dịch TK'!$C$5:$C$504,$A14) -> 2100 | C14: =SUMIFS('Giao dịch TK'!$E$5:$E$504,'Giao dịch TK'!$C$5:$C$504,$A14) -> 0 | D14: =SUMIFS('Giao dịch TK'!$F$5:$F$504,'Giao dịch TK'!$C$5:$C$504,$A14) -> 0 | E14: =B14-D14 -> 2100 | F14: =COUNTIFS('Giao dịch TK'!$C$5:$C$504,$A14) -> 2
A15: diem1995 | B15: =SUMIFS('Giao dịch TK'!$D$5:$D$504,'Giao dịch TK'!$C$5:$C$504,$A15) -> 100 | C15: =SUMIFS('Giao dịch TK'!$E$5:$E$504,'Giao dịch TK'!$C$5:$C$504,$A15) -> 0 | D15: =SUMIFS('Giao dịch TK'!$F$5:$F$504,'Giao dịch TK'!$C$5:$C$504,$A15) -> 0 | E15: =B15-D15 -> 100 | F15: =COUNTIFS('Giao dịch TK'!$C$5:$C$504,$A15) -> 1
A16: haidang186 | B16: =SUMIFS('Giao dịch TK'!$D$5:$D$504,'Giao dịch TK'!$C$5:$C$504,$A16) -> 200 | C16: =SUMIFS('Giao dịch TK'!$E$5:$E$504,'Giao dịch TK'!$C$5:$C$504,$A16) -> 0 | D16: =SUMIFS('Giao dịch TK'!$F$5:$F$504,'Giao dịch TK'!$C$5:$C$504,$A16) -> 0 | E16: =B16-D16 -> 200 | F16: =COUNTIFS('Giao dịch TK'!$C$5:$C$504,$A16) -> 2
... A48: zinssha | B48: =SUMIFS('Giao dịch TK'!$D$5:$D$504,'Giao dịch TK'!$C$5:$C$504,$A48) -> 5000 | C48: =SUMIFS('Giao dịch TK'!$E$5:$E$504,'Giao dịch TK'!$C$5:$C$504,$A48) -> 15000 | D48: =SUMIFS('Giao dịch TK'!$F$5:$F$504,'Giao dịch TK'!$C$5:$C$504,$A48) -> 0 | E48: =B48-D48 -> 5000 | F48: =COUNTIFS('Giao dịch TK'!$C$5:$C$504,$A48) -> 1

Sheet Đối chiếu file cũ
A1: ĐỐI CHIẾU VỚI CÁC SỐ TỔNG GÕ TAY TRONG FILE CŨ
A2: Cột 'File cũ' là số chép từ file SU.xlsx. Cột 'Tính lại' là công thức trên dữ liệu mới.
A4: Hạng mục | B4: Ô file cũ | C4: File cũ | D4: Tính lại | E4: Chênh lệch | F4: Kết quả
A5: WINDI 01/10 — Nạp + Đơn | B5: tháng 10!G4 | C5: 34550 | D5: =SUMIFS('Giao dịch TK'!$D$5:$D$504,'Giao dịch TK'!$B$5:$B$504,"WINDI",'Giao dịch TK'!$A$5:$A$504,DATE(2026,10,1))+SUMIFS('Giao dịch TK'!$E$5:$E$504,'Giao dịch TK'!$B$5:$B$504,"WINDI",'Giao dịch TK'!$A$5:$A$504,DATE(2026,10,1)) -> 34550 | E5: =D5-C5 -> 0 | F5: =IF(E5=0,"✓ Khớp","⚠ Lệch") -> ✓ Khớp
A6: WINDI 01/10 — Rút | B6: tháng 10!F14 | C6: 408 | D6: =SUMIFS('Giao dịch TK'!$F$5:$F$504,'Giao dịch TK'!$B$5:$B$504,"WINDI",'Giao dịch TK'!$A$5:$A$504,DATE(2026,10,1)) -> 408 | E6: =D6-C6 -> 0 | F6: =IF(E6=0,"✓ Khớp","⚠ Lệch") -> ✓ Khớp
A7: WINDI 02/10 — Nạp + Đơn | B7: tháng 10!G17 | C7: 19850 | D7: =SUMIFS('Giao dịch TK'!$D$5:$D$504,'Giao dịch TK'!$B$5:$B$504,"WINDI",'Giao dịch TK'!$A$5:$A$504,DATE(2026,10,2))+SUMIFS('Giao dịch TK'!$E$5:$E$504,'Giao dịch TK'!$B$5:$B$504,"WINDI",'Giao dịch TK'!$A$5:$A$504,DATE(2026,10,2)) -> 19850 | E7: =D7-C7 -> 0 | F7: =IF(E7=0,"✓ Khớp","⚠ Lệch") -> ✓ Khớp
A8: WINDI 02/10 — Rút | B8: tháng 10!F23 | C8: 1215 | D8: =SUMIFS('Giao dịch TK'!$F$5:$F$504,'Giao dịch TK'!$B$5:$B$504,"WINDI",'Giao dịch TK'!$A$5:$A$504,DATE(2026,10,2)) -> 1161 | E8: =D8-C8 -> -54 | F8: =IF(E8=0,"✓ Khớp","⚠ Lệch") -> ⚠ Lệch
A9: WINDI 03/10 — Nạp + Đơn | B9: tháng 10!G26 | C9: 9250 | D9: =SUMIFS('Giao dịch TK'!$D$5:$D$504,'Giao dịch TK'!$B$5:$B$504,"WINDI",'Giao dịch TK'!$A$5:$A$504,DATE(2026,10,3))+SUMIFS('Giao dịch TK'!$E$5:$E$504,'Giao dịch TK'!$B$5:$B$504,"WINDI",'Giao dịch TK'!$A$5:$A$504,DATE(2026,10,3)) -> 9250 | E9: =D9-C9 -> 0 | F9: =IF(E9=0,"✓ Khớp","⚠ Lệch") -> ✓ Khớp
A10: WINDI 04/10 — Nạp + Đơn | B10: tháng 10!G28 | C10: 10000 | D10: =SUMIFS('Giao dịch TK'!$D$5:$D$504,'Giao dịch TK'!$B$5:$B$504,"WINDI",'Giao dịch TK'!$A$5:$A$504,DATE(2026,10,4))+SUMIFS('Giao dịch TK'!$E$5:$E$504,'Giao dịch TK'!$B$5:$B$504,"WINDI",'Giao dịch TK'!$A$5:$A$504,DATE(2026,10,4)) -> 10000 | E10: =D10-C10 -> 0 | F10: =IF(E10=0,"✓ Khớp","⚠ Lệch") -> ✓ Khớp
A11: CAO TIẾN 01/10 — Nạp | B11: tháng 10!O4 | C11: 8200 | D11: =SUMIFS('Giao dịch TK'!$D$5:$D$504,'Giao dịch TK'!$B$5:$B$504,"CAO TIẾN",'Giao dịch TK'!$A$5:$A$504,DATE(2026,10,1)) -> 8200 | E11: =D11-C11 -> 0 | F11: =IF(E11=0,"✓ Khớp","⚠ Lệch") -> ✓ Khớp
A12: CAO TIẾN 02/10 — Nạp | B12: tháng 10!O11 | C12: 150 | D12: =SUMIFS('Giao dịch TK'!$D$5:$D$504,'Giao dịch TK'!$B$5:$B$504,"CAO TIẾN",'Giao dịch TK'!$A$5:$A$504,DATE(2026,10,2)) -> 150 | E12: =D12-C12 -> 0 | F12: =IF(E12=0,"✓ Khớp","⚠ Lệch") -> ✓ Khớp
A13: SU 01/10 — Nạp − Rút | B13: tháng 10!W4 | C13: 9 | D13: =SUMIFS('Giao dịch TK'!$D$5:$D$504,'Giao dịch TK'!$B$5:$B$504,"SU",'Giao dịch TK'!$A$5:$A$504,DATE(2026,10,1))-SUMIFS('Giao dịch TK'!$F$5:$F$504,'Giao dịch TK'!$B$5:$B$504,"SU",'Giao dịch TK'!$A$5:$A$504,DATE(2026,10,1)) -> 9 | E13: =D13-C13 -> 0 | F13: =IF(E13=0,"✓ Khớp","⚠ Lệch") -> ✓ Khớp
A14: SU 02/10 — Nạp − Rút | B14: tháng 10!W6 | C14: 50 | D14: =SUMIFS('Giao dịch TK'!$D$5:$D$504,'Giao dịch TK'!$B$5:$B$504,"SU",'Giao dịch TK'!$A$5:$A$504,DATE(2026,10,2))-SUMIFS('Giao dịch TK'!$F$5:$F$504,'Giao dịch TK'!$B$5:$B$504,"SU",'Giao dịch TK'!$A$5:$A$504,DATE(2026,10,2)) -> 50 | E14: =D14-C14 -> 0 | F14: =IF(E14=0,"✓ Khớp","⚠ Lệch") -> ✓ Khớp
A15: Tổng hoa hồng (HH THANG 10) | B15: HH THANG 10!D2:D5 | C15: 42572 | D15: =SUMIFS('Thu Chi'!$E$5:$E$504,'Thu Chi'!$C$5:$C$504,"Hoa hồng") -> 42572 | E15: =D15-C15 -> 0 | F15: =IF(E15=0,"✓ Khớp","⚠ Lệch") -> ✓ Khớp
A18: Các điểm cần xác nhận (đã tô cam trong sheet Thu Chi / Giao dịch TK):
A19: • WINDI 02/10: file cũ ghi tổng rút 1.215 nhưng 206 + 955 = 1.161 (lệch 54).
A20: • Sheet 'su' 04/10 nhận 300.000 — lớn bất thường, có thể gõ thừa số 0.
A21: • quoc2004 có đơn 4.600 cả ngày 03/10 và 05/10 — có thể nhập trùng.
A22: • THU CHI 04/10 'su mua ss 4600' không có trong sheet 'su'.
A23: • 'vansuol123' và 'vansuong123' có thể là cùng 1 TK.
A24: • Đại lý Ngọc Linh 65 không có ngày giao dịch; 2 dòng thiếu tên TK.
A25: • Khoản 'su mua nl 2300' và 'HH WINDY 23772' có ở 2 sheet cũ — file mới chỉ ghi 1 lần.
A26: • Sheet 'su' có nhiều khoản chỉ ghi 'GIA' — đã xếp loại 'Khác', nên bổ sung nội dung.
A27: • Đơn vị tiền không ghi trong file cũ (có thể là nghìn đồng) — giữ nguyên số.
